<?xml version="1.0" ?>
<!-- =================================================================================== -->
<!-- |    This document was autogenerated by xacro from /home/user/projects/shadow_robot/base/src/dx_system/dx_launch/description/dexee_ur.urdf.xacro | -->
<!-- |    EDITING THIS FILE BY HAND IS NOT RECOMMENDED                                 | -->
<!-- =================================================================================== -->
<!--
 Copyright (C) 2024-2025 Shadow Robot Company Ltd - All Rights Reserved. Proprietary and Confidential.
 Unauthorized copying of the content in this file, via any medium is strictly prohibited.
-->
<robot name="ur_dex" xmlns:controller="http://playerstage.sourceforge.net/gazebo/xmlschema/#controller" xmlns:interface="http://playerstage.sourceforge.net/gazebo/xmlschema/#interface" xmlns:sensor="http://playerstage.sourceforge.net/gazebo/xmlschema/#sensor">
    <link name="world" />
    <!--
    Base UR robot series xacro macro.

    NOTE: this is NOT a URDF. It cannot directly be loaded by consumers
    expecting a flattened '.urdf' file. See the top-level '.xacro' for that
    (but note: that .xacro must still be processed by the xacro command).

    For use in '.launch' files: use one of the 'load_urX.launch' convenience
    launch files.

    This file models the base kinematic chain of a UR robot, which then gets
    parameterised by various configuration files to convert it into a UR3(e),
    UR5(e), UR10(e), UR16e, UR20 or UR30.

    NOTE: the default kinematic parameters (ie: link lengths, frame locations,
    offets, etc) do not correspond to any particular robot. They are defaults
    only. There WILL be non-zero offsets between the Forward Kinematics results
    in TF (ie: robot_state_publisher) and the values reported by the Teach
    Pendant.

    For accurate (and robot-specific) transforms, the 'kinematics_parameters_file'
    parameter MUST point to a .yaml file containing the appropriate values for
    the targetted robot.

    If using the UniversalRobots/Universal_Robots_ROS_Driver, follow the steps
    described in the readme of that repository to extract the kinematic
    calibration from the controller and generate the required .yaml file.

    Main author of the migration to yaml configs: Ludovic Delval.

    Contributors to previous versions (in no particular order):

     - Felix Messmer
     - Kelsey Hawkins
     - Wim Meeussen
     - Shaun Edwards
     - Nadia Hammoudeh Garcia
     - Dave Hershberger
     - G. vd. Hoorn
     - Philip Long
     - Dave Coleman
     - Miguel Prada
     - Mathias Luedtke
     - Marcel Schnirring
     - Felix von Drigalski
     - Felix Exner
     - Jimmy Da Silva
     - Ajit Krisshna N L
     - Muhammad Asif Rana
  -->
    <!--
    NOTE: the macro defined in this file is NOT part of the public API of this
          package. Users CANNOT rely on this file being available, or stored in
          this location. Nor can they rely on the existence of the macro.
  -->
    <transmission name="a0_shoulder_pan_trans">
        <type>transmission_interface/SimpleTransmission</type>
        <joint name="a0_shoulder_pan_joint">
            <hardwareInterface>hardware_interface/PositionJointInterface</hardwareInterface>
        </joint>
        <actuator name="a0_shoulder_pan_motor">
            <mechanicalReduction>1</mechanicalReduction>
            <hardwareInterface>hardware_interface/EffortJointInterface</hardwareInterface>
        </actuator>
    </transmission>
    <transmission name="a0_shoulder_lift_trans">
        <type>transmission_interface/SimpleTransmission</type>
        <joint name="a0_shoulder_lift_joint">
            <hardwareInterface>hardware_interface/PositionJointInterface</hardwareInterface>
        </joint>
        <actuator name="a0_shoulder_lift_motor">
            <mechanicalReduction>1</mechanicalReduction>
            <hardwareInterface>hardware_interface/EffortJointInterface</hardwareInterface>
        </actuator>
    </transmission>
    <transmission name="a0_elbow_trans">
        <type>transmission_interface/SimpleTransmission</type>
        <joint name="a0_elbow_joint">
            <hardwareInterface>hardware_interface/PositionJointInterface</hardwareInterface>
        </joint>
        <actuator name="a0_elbow_motor">
            <mechanicalReduction>1</mechanicalReduction>
            <hardwareInterface>hardware_interface/EffortJointInterface</hardwareInterface>
        </actuator>
    </transmission>
    <transmission name="a0_wrist_1_trans">
        <type>transmission_interface/SimpleTransmission</type>
        <joint name="a0_wrist_1_joint">
            <hardwareInterface>hardware_interface/PositionJointInterface</hardwareInterface>
        </joint>
        <actuator name="a0_wrist_1_motor">
            <mechanicalReduction>1</mechanicalReduction>
            <hardwareInterface>hardware_interface/EffortJointInterface</hardwareInterface>
        </actuator>
    </transmission>
    <transmission name="a0_wrist_2_trans">
        <type>transmission_interface/SimpleTransmission</type>
        <joint name="a0_wrist_2_joint">
            <hardwareInterface>hardware_interface/PositionJointInterface</hardwareInterface>
        </joint>
        <actuator name="a0_wrist_2_motor">
            <mechanicalReduction>1</mechanicalReduction>
            <hardwareInterface>hardware_interface/EffortJointInterface</hardwareInterface>
        </actuator>
    </transmission>
    <transmission name="a0_wrist_3_trans">
        <type>transmission_interface/SimpleTransmission</type>
        <joint name="a0_wrist_3_joint">
            <hardwareInterface>hardware_interface/PositionJointInterface</hardwareInterface>
        </joint>
        <actuator name="a0_wrist_3_motor">
            <mechanicalReduction>1</mechanicalReduction>
            <hardwareInterface>hardware_interface/EffortJointInterface</hardwareInterface>
        </actuator>
    </transmission>
    <!-- links: main serial chain -->
    <link name="a0_base_link" />
    <link name="a0_base_link_inertia">
        <visual>
            <origin rpy="0 0 3.141592653589793" xyz="0 0 0" />
            <geometry>
                <mesh filename="package://ur_description/meshes/ur10e/visual/base.dae" />
            </geometry>
            <material name="LightGrey">
                <color rgba="0.7 0.7 0.7 1.0" />
            </material>
        </visual>
        <collision>
            <origin rpy="0 0 3.141592653589793" xyz="0 0 0" />
            <geometry>
                <mesh filename="package://ur_description/meshes/ur10e/collision/base.stl" />
            </geometry>
        </collision>
        <inertial>
            <mass value="4.0" />
            <origin rpy="0 0 0" xyz="0 0 0" />
            <inertia ixx="0.0061063308908" ixy="0.0" ixz="0.0" iyy="0.0061063308908" iyz="0.0" izz="0.01125" />
        </inertial>
    </link>
    <link name="a0_shoulder_link">
        <visual>
            <origin rpy="0 0 3.141592653589793" xyz="0 0 0" />
            <geometry>
                <mesh filename="package://ur_description/meshes/ur10e/visual/shoulder.dae" />
            </geometry>
            <material name="LightGrey">
                <color rgba="0.7 0.7 0.7 1.0" />
            </material>
        </visual>
        <collision>
            <origin rpy="0 0 3.141592653589793" xyz="0 0 0" />
            <geometry>
                <mesh filename="package://ur_description/meshes/ur10e/collision/shoulder.stl" />
            </geometry>
        </collision>
        <inertial>
            <mass value="7.778" />
            <origin rpy="0 0 0" xyz="0 0 0" />
            <inertia ixx="0.03147431257693659" ixy="0.0" ixz="0.0" iyy="0.03147431257693659" iyz="0.0" izz="0.021875624999999996" />
        </inertial>
    </link>
    <link name="a0_upper_arm_link">
        <visual>
            <origin rpy="1.5707963267948966 0 -1.5707963267948966" xyz="0 0 0.1762" />
            <geometry>
                <mesh filename="package://ur_description/meshes/ur10e/visual/upperarm.dae" />
            </geometry>
            <material name="LightGrey">
                <color rgba="0.7 0.7 0.7 1.0" />
            </material>
        </visual>
        <collision>
            <origin rpy="1.5707963267948966 0 -1.5707963267948966" xyz="0 0 0.1762" />
            <geometry>
                <mesh filename="package://ur_description/meshes/ur10e/collision/upperarm.stl" />
            </geometry>
        </collision>
        <inertial>
            <mass value="12.93" />
            <origin rpy="0 1.5707963267948966 0" xyz="-0.306 0.0 0.175" />
            <inertia ixx="0.42175380379841093" ixy="0.0" ixz="0.0" iyy="0.42175380379841093" iyz="0.0" izz="0.03636562499999999" />
        </inertial>
    </link>
    <link name="a0_forearm_link">
        <visual>
            <origin rpy="1.5707963267948966 0 -1.5707963267948966" xyz="0 0 0.0393" />
            <geometry>
                <mesh filename="package://ur_description/meshes/ur10e/visual/forearm.dae" />
            </geometry>
            <material name="LightGrey">
                <color rgba="0.7 0.7 0.7 1.0" />
            </material>
        </visual>
        <collision>
            <origin rpy="1.5707963267948966 0 -1.5707963267948966" xyz="0 0 0.0393" />
            <geometry>
                <mesh filename="package://ur_description/meshes/ur10e/collision/forearm.stl" />
            </geometry>
        </collision>
        <inertial>
            <mass value="3.87" />
            <origin rpy="0 1.5707963267948966 0" xyz="-0.285775 0.0 0.0393" />
            <inertia ixx="0.11079302548902206" ixy="0.0" ixz="0.0" iyy="0.11079302548902206" iyz="0.0" izz="0.010884375" />
        </inertial>
    </link>
    <link name="a0_wrist_1_link">
        <visual>
            <!-- TODO: Move this to a parameter -->
            <origin rpy="1.5707963267948966 0 0" xyz="0 0 -0.135" />
            <geometry>
                <mesh filename="package://ur_description/meshes/ur10e/visual/wrist1.dae" />
            </geometry>
            <material name="LightGrey">
                <color rgba="0.7 0.7 0.7 1.0" />
            </material>
        </visual>
        <collision>
            <origin rpy="1.5707963267948966 0 0" xyz="0 0 -0.135" />
            <geometry>
                <mesh filename="package://ur_description/meshes/ur10e/collision/wrist1.stl" />
            </geometry>
        </collision>
        <inertial>
            <mass value="1.96" />
            <origin rpy="0 0 0" xyz="0 0 0" />
            <inertia ixx="0.005108247956699999" ixy="0.0" ixz="0.0" iyy="0.005108247956699999" iyz="0.0" izz="0.005512499999999999" />
        </inertial>
    </link>
    <link name="a0_wrist_2_link">
        <visual>
            <origin rpy="0 0 0" xyz="0 0 -0.12" />
            <geometry>
                <mesh filename="package://ur_description/meshes/ur10e/visual/wrist2.dae" />
            </geometry>
            <material name="LightGrey">
                <color rgba="0.7 0.7 0.7 1.0" />
            </material>
        </visual>
        <collision>
            <origin rpy="0 0 0" xyz="0 0 -0.12" />
            <geometry>
                <mesh filename="package://ur_description/meshes/ur10e/collision/wrist2.stl" />
            </geometry>
        </collision>
        <inertial>
            <mass value="1.96" />
            <origin rpy="0 0 0" xyz="0 0 0" />
            <inertia ixx="0.005108247956699999" ixy="0.0" ixz="0.0" iyy="0.005108247956699999" iyz="0.0" izz="0.005512499999999999" />
        </inertial>
    </link>
    <link name="a0_wrist_3_link">
        <visual>
            <origin rpy="1.5707963267948966 0 0" xyz="0 0 -0.1168" />
            <geometry>
                <mesh filename="package://ur_description/meshes/ur10e/visual/wrist3.dae" />
            </geometry>
            <material name="LightGrey">
                <color rgba="0.7 0.7 0.7 1.0" />
            </material>
        </visual>
        <collision>
            <origin rpy="1.5707963267948966 0 0" xyz="0 0 -0.1168" />
            <geometry>
                <mesh filename="package://ur_description/meshes/ur10e/collision/wrist3.stl" />
            </geometry>
        </collision>
        <inertial>
            <mass value="0.202" />
            <origin rpy="0 0 0" xyz="0.0 0.0 -0.025" />
            <inertia ixx="0.00014434577559500002" ixy="0.0" ixz="0.0" iyy="0.00014434577559500002" iyz="0.0" izz="0.00020452500000000002" />
        </inertial>
    </link>
    <!-- joints: main serial chain -->
    <joint name="a0_base_link-base_link_inertia" type="fixed">
        <parent link="a0_base_link" />
        <child link="a0_base_link_inertia" />
        <!-- 'base_link' is REP-103 aligned (so X+ forward), while the internal
           frames of the robot/controller have X+ pointing backwards.
           Use the joint between 'base_link' and 'base_link_inertia' (a dummy
           link/frame) to introduce the necessary rotation over Z (of pi rad).
      -->
        <origin rpy="0 0 3.141592653589793" xyz="0 0 0" />
    </joint>
    <joint name="a0_shoulder_pan_joint" type="revolute">
        <parent link="a0_base_link_inertia" />
        <child link="a0_shoulder_link" />
        <origin rpy="0 0 0" xyz="0 0 0.1807" />
        <axis xyz="0 0 1" />
        <limit effort="330.0" lower="-6.283185307179586" upper="6.283185307179586" velocity="2.0943951023931953" />
        <dynamics damping="0" friction="0" />
    </joint>
    <joint name="a0_shoulder_lift_joint" type="revolute">
        <parent link="a0_shoulder_link" />
        <child link="a0_upper_arm_link" />
        <origin rpy="1.570796327 0 0" xyz="0 0 0" />
        <axis xyz="0 0 1" />
        <limit effort="330.0" lower="-6.283185307179586" upper="6.283185307179586" velocity="2.0943951023931953" />
        <dynamics damping="0" friction="0" />
    </joint>
    <joint name="a0_elbow_joint" type="revolute">
        <parent link="a0_upper_arm_link" />
        <child link="a0_forearm_link" />
        <origin rpy="0 0 0" xyz="-0.6127 0 0" />
        <axis xyz="0 0 1" />
        <limit effort="150.0" lower="-3.141592653589793" upper="3.141592653589793" velocity="3.141592653589793" />
        <dynamics damping="0" friction="0" />
    </joint>
    <joint name="a0_wrist_1_joint" type="revolute">
        <parent link="a0_forearm_link" />
        <child link="a0_wrist_1_link" />
        <origin rpy="0 0 0" xyz="-0.57155 0 0.17415" />
        <axis xyz="0 0 1" />
        <limit effort="56.0" lower="-6.283185307179586" upper="6.283185307179586" velocity="3.141592653589793" />
        <dynamics damping="0" friction="0" />
    </joint>
    <joint name="a0_wrist_2_joint" type="revolute">
        <parent link="a0_wrist_1_link" />
        <child link="a0_wrist_2_link" />
        <origin rpy="1.570796327 0 0" xyz="0 -0.11985 -2.458164590756244e-11" />
        <axis xyz="0 0 1" />
        <limit effort="56.0" lower="-6.283185307179586" upper="6.283185307179586" velocity="3.141592653589793" />
        <dynamics damping="0" friction="0" />
    </joint>
    <joint name="a0_wrist_3_joint" type="revolute">
        <parent link="a0_wrist_2_link" />
        <child link="a0_wrist_3_link" />
        <origin rpy="1.570796326589793 3.141592653589793 3.141592653589793" xyz="0 0.11655 -2.390480459346185e-11" />
        <axis xyz="0 0 1" />
        <limit effort="56.0" lower="-6.283185307179586" upper="6.283185307179586" velocity="3.141592653589793" />
        <dynamics damping="0" friction="0" />
    </joint>
    <!-- ROS-Industrial 'base' frame: base_link to UR 'Base' Coordinates transform -->
    <link name="a0_base" />
    <joint name="a0_base_link-base_fixed_joint" type="fixed">
        <!-- Note the rotation over Z of pi radians: as base_link is REP-103
           aligned (ie: has X+ forward, Y+ left and Z+ up), this is needed
           to correctly align 'base' with the 'Base' coordinate system of
           the UR controller.
      -->
        <origin rpy="0 0 3.141592653589793" xyz="0 0 0" />
        <parent link="a0_base_link" />
        <child link="a0_base" />
    </joint>
    <!-- ROS-Industrial 'flange' frame: attachment point for EEF models -->
    <link name="a0_flange" />
    <joint name="a0_wrist_3-flange" type="fixed">
        <parent link="a0_wrist_3_link" />
        <child link="a0_flange" />
        <origin rpy="0 -1.5707963267948966 -1.5707963267948966" xyz="0 0 0" />
    </joint>
    <!-- ROS-Industrial 'tool0' frame: all-zeros tool frame -->
    <link name="a0_tool0" />
    <joint name="a0_flange-tool0" type="fixed">
        <!-- default toolframe: X+ left, Y+ up, Z+ front -->
        <origin rpy="1.5707963267948966 0 1.5707963267948966" xyz="0 0 0" />
        <parent link="a0_flange" />
        <child link="a0_tool0" />
    </joint>
    <link name="h0_hand_base">
        <inertial>
            <origin rpy="0 0 0" xyz="0.00024269 0.0064896 0.05011689" />
            <mass value="0.53506724" />
            <inertia ixx="0.00235606" ixy="-0.00000318" ixz="0.00001251" iyy="0.00262644" iyz="-0.00010584" izz="0.00095084" />
        </inertial>
        <visual>
            <origin rpy="0 0 0" xyz="0 0 0" />
            <geometry>
                <mesh filename="package://dx_robot/description/meshes/dx_e3r3_finger/H_Base.STL" />
            </geometry>
            <material name="">
                <color rgba="0.898039215686275 0.917647058823529 0.929411764705882 1" />
            </material>
        </visual>
        <collision>
            <origin rpy="0 0 0" xyz="0 0 0" />
            <geometry>
                <mesh filename="package://dx_robot/description/meshes/dx_e3r3_finger/collision/Hand_Base.STL" />
            </geometry>
        </collision>
    </link>
    <joint name="h0_world_joint_F0" type="fixed">
        <origin rpy="-1.5707 0 0" xyz="0 0.05 0.017" />
        <parent link="h0_hand_base" />
        <child link="h0_F0_base" />
    </joint>
    <link name="h0_F0_base">
        <inertial>
            <origin rpy="0 0 0" xyz="0.00004454 0.00736569 0.08093736" />
            <mass value="0.89937782" />
            <inertia ixx="0.00186283" ixy="-0.00000176" ixz="-0.00000296" iyy="0.00181365" iyz="0.00004212" izz="0.00058221" />
        </inertial>
        <visual>
            <origin rpy="1.5707 0 0" xyz="0 0 0" />
            <geometry>
                <mesh filename="package://dx_robot/description/meshes/dx_e3r3_finger/F0_base.STL" />
            </geometry>
            <material name="">
                <color rgba="0.75294 0.75294 0.75294 1" />
            </material>
        </visual>
        <collision>
            <origin rpy="1.5707 0 0" xyz="0 0 0" />
            <geometry>
                <mesh filename="package://dx_robot/description/meshes/dx_e3r3_finger/collision/F0_base.STL" />
            </geometry>
        </collision>
    </link>
    <link name="h0_F0_J0_link">
        <inertial>
            <origin rpy="0 0 0" xyz="-0.00017293 -0.01537184 0.00956679" />
            <mass value="0.13077995" />
            <inertia ixx="0.00005895" ixy="0.00000007" ixz="0.00000064" iyy="0.00004702" iyz="-0.00000971" izz="0.00003911" />
        </inertial>
        <visual>
            <origin rpy="0 0 0" xyz="0 0.077 0" />
            <geometry>
                <mesh filename="package://dx_robot/description/meshes/dx_e3r3_finger/F0_J0_link.STL" />
            </geometry>
            <material name="">
                <color rgba="0.75294 0.75294 0.75294 1" />
            </material>
        </visual>
        <collision>
            <origin rpy="0 0 0" xyz="0 0.077 0" />
            <geometry>
                <mesh filename="package://dx_robot/description/meshes/dx_e3r3_finger/collision/F0_J0_link.STL" />
            </geometry>
        </collision>
    </link>
    <joint name="h0_F0_J0" type="revolute">
        <origin rpy="2.0944 0 0" xyz="0 -0.14073 -0.051327" />
        <parent link="h0_F0_base" />
        <child link="h0_F0_J0_link" />
        <axis xyz="0 -1 0" />
        <limit effort="1.5" lower="-0.8727" upper="0.8727" velocity="2" />
    </joint>
    <link name="h0_F0_proximal">
        <inertial>
            <origin rpy="0 0 0" xyz="-0.00020256 0.0024322 0.02375091" />
            <mass value="0.09614332" />
            <inertia ixx="0.00004332" ixy="-0.00000017" ixz="-0.00000349" iyy="0.00004756" iyz="0.00000055" izz="0.00002008" />
        </inertial>
        <visual>
            <origin rpy="0 0 0" xyz="0 0 0" />
            <geometry>
                <mesh filename="package://dx_robot/description/meshes/dx_e3r3_finger/F0_proximal.STL" />
            </geometry>
            <material name="">
                <color rgba="0.75294 0.75294 0.75294 1" />
            </material>
        </visual>
        <collision>
            <origin rpy="0 0 0" xyz="0 0 0" />
            <geometry>
                <mesh filename="package://dx_robot/description/meshes/dx_e3r3_finger/collision/F0_proximal.STL" />
            </geometry>
        </collision>
    </link>
    <joint name="h0_F0_J1" type="revolute">
        <origin rpy="0 0 0" xyz="0 0.0765883365730207 0.0299999999999999" />
        <parent link="h0_F0_J0_link" />
        <child link="h0_F0_proximal" />
        <axis xyz="1 0 0" />
        <limit effort="1.2" lower="-1.396" upper="0.785" velocity="2" />
    </joint>
    <link name="h0_F0_middle">
        <inertial>
            <origin rpy="0 0 0" xyz="-0.00026744 -0.00004338 0.01669764" />
            <mass value="0.05585897" />
            <inertia ixx="0.00001447" ixy="-0.00000005" ixz="-0.00000004" iyy="0.00001686" iyz="-0.00000007" izz="0.00000973" />
        </inertial>
        <visual>
            <origin rpy="0 0 0" xyz="0 0 0" />
            <geometry>
                <mesh filename="package://dx_robot/description/meshes/dx_e3r3_finger/F0_middle.STL" />
            </geometry>
            <material name="">
                <color rgba="0.75294 0.75294 0.75294 1" />
            </material>
        </visual>
        <collision>
            <origin rpy="0 0 0" xyz="0 0 0" />
            <geometry>
                <mesh filename="package://dx_robot/description/meshes/dx_e3r3_finger/collision/F0_middle.STL" />
            </geometry>
        </collision>
    </link>
    <joint name="h0_F0_J2" type="revolute">
        <origin rpy="0 0 0" xyz="0 0 0.05" />
        <parent link="h0_F0_proximal" />
        <child link="h0_F0_middle" />
        <axis xyz="1 0 0" />
        <limit effort="0.7" lower="0" upper="1.396" velocity="2" />
    </joint>
    <link name="h0_F0_distal">
        <inertial>
            <origin rpy="0 0 0" xyz="0.00084325 0.00164346 0.01482169" />
            <mass value="0.02766365" />
            <inertia ixx="0.0000051" ixy="0" ixz="0.00000028" iyy="0.00000506" iyz="-0.00000034" izz="0.00000198" />
        </inertial>
        <visual>
            <origin rpy="0 0 0" xyz="0 0 0" />
            <geometry>
                <mesh filename="package://dx_robot/description/meshes/dx_e3r3_finger/F0_distal.STL" />
            </geometry>
            <material name="">
                <color rgba="0.75294 0.75294 0.75294 1" />
            </material>
        </visual>
        <collision>
            <origin rpy="0 0 0" xyz="0 0 0" />
            <geometry>
                <mesh filename="package://dx_robot/description/meshes/dx_e3r3_finger/collision/F0_distal.STL" />
            </geometry>
        </collision>
    </link>
    <joint name="h0_F0_J3" type="revolute">
        <origin rpy="0 0 0" xyz="0 0 0.035" />
        <parent link="h0_F0_middle" />
        <child link="h0_F0_distal" />
        <axis xyz="1 0 0" />
        <limit effort="0.35" lower="-0.523" upper="1.485" velocity="0.2" />
    </joint>
    <link name="h0_F0_tip" />
    <joint name="h0_F0_distal_tip" type="fixed">
        <parent link="h0_F0_distal" />
        <child link="h0_F0_tip" />
        <origin rpy="0 0 0" xyz="0 0.003 0.033" />
    </joint>
    <!-- These transmissions are wrongly configured and fail to be loaded by the real robot -->
    <!-- We still need to define them in order to be able to launch the robot in simulation -->
    <transmission name="trans_h0_F0_J0">
        <type>UnusedTransmission</type>
        <joint name="h0_F0_J0">
            <hardwareInterface>hardware_interface/EffortJointInterface</hardwareInterface>
        </joint>
        <actuator name="h0_F0_J0_motor">
            <!-- <hardwareInterface>hardware_interface/EffortJointInterface</hardwareInterface> -->
            <mechanicalReduction>1</mechanicalReduction>
        </actuator>
    </transmission>
    <transmission name="trans_h0_F0_J1">
        <type>UnusedTransmission</type>
        <joint name="h0_F0_J1">
            <hardwareInterface>hardware_interface/EffortJointInterface</hardwareInterface>
        </joint>
        <actuator name="h0_F0_J1_motor">
            <!-- <hardwareInterface>hardware_interface/EffortJointInterface</hardwareInterface> -->
            <mechanicalReduction>1</mechanicalReduction>
        </actuator>
    </transmission>
    <transmission name="trans_h0_F0_J2">
        <type>UnusedTransmission</type>
        <joint name="h0_F0_J2">
            <hardwareInterface>hardware_interface/EffortJointInterface</hardwareInterface>
        </joint>
        <actuator name="h0_F0_J2_motor">
            <!-- <hardwareInterface>hardware_interface/EffortJointInterface</hardwareInterface> -->
            <mechanicalReduction>1</mechanicalReduction>
        </actuator>
    </transmission>
    <transmission name="trans_h0_F0_J3">
        <type>UnusedTransmission</type>
        <joint name="h0_F0_J3">
            <hardwareInterface>hardware_interface/EffortJointInterface</hardwareInterface>
        </joint>
        <actuator name="h0_F0_J3_motor">
            <!-- <hardwareInterface>hardware_interface/EffortJointInterface</hardwareInterface> -->
            <mechanicalReduction>1</mechanicalReduction>
        </actuator>
    </transmission>
    <joint name="h0_world_joint_F1" type="fixed">
        <origin rpy="-1.5707 0 -2.8159" xyz="0.0384 -0.0287 0.017" />
        <parent link="h0_hand_base" />
        <child link="h0_F1_base" />
    </joint>
    <link name="h0_F1_base">
        <inertial>
            <origin rpy="0 0 0" xyz="0.00004454 0.00736569 0.08093736" />
            <mass value="0.89937782" />
            <inertia ixx="0.00186283" ixy="-0.00000176" ixz="-0.00000296" iyy="0.00181365" iyz="0.00004212" izz="0.00058221" />
        </inertial>
        <visual>
            <origin rpy="1.5707 0 0" xyz="0 0 0" />
            <geometry>
                <mesh filename="package://dx_robot/description/meshes/dx_e3r3_finger/F0_base.STL" />
            </geometry>
            <material name="">
                <color rgba="0.75294 0.75294 0.75294 1" />
            </material>
        </visual>
        <collision>
            <origin rpy="1.5707 0 0" xyz="0 0 0" />
            <geometry>
                <mesh filename="package://dx_robot/description/meshes/dx_e3r3_finger/collision/F0_base.STL" />
            </geometry>
        </collision>
    </link>
    <link name="h0_F1_J0_link">
        <inertial>
            <origin rpy="0 0 0" xyz="-0.00017293 -0.01537184 0.00956679" />
            <mass value="0.13077995" />
            <inertia ixx="0.00005895" ixy="0.00000007" ixz="0.00000064" iyy="0.00004702" iyz="-0.00000971" izz="0.00003911" />
        </inertial>
        <visual>
            <origin rpy="0 0 0" xyz="0 0.077 0" />
            <geometry>
                <mesh filename="package://dx_robot/description/meshes/dx_e3r3_finger/F0_J0_link.STL" />
            </geometry>
            <material name="">
                <color rgba="0.75294 0.75294 0.75294 1" />
            </material>
        </visual>
        <collision>
            <origin rpy="0 0 0" xyz="0 0.077 0" />
            <geometry>
                <mesh filename="package://dx_robot/description/meshes/dx_e3r3_finger/collision/F0_J0_link.STL" />
            </geometry>
        </collision>
    </link>
    <joint name="h0_F1_J0" type="revolute">
        <origin rpy="2.0944 0 0" xyz="0 -0.14073 -0.051327" />
        <parent link="h0_F1_base" />
        <child link="h0_F1_J0_link" />
        <axis xyz="0 -1 0" />
        <limit effort="1.5" lower="-0.8727" upper="0.8727" velocity="2" />
    </joint>
    <link name="h0_F1_proximal">
        <inertial>
            <origin rpy="0 0 0" xyz="-0.00020256 0.0024322 0.02375091" />
            <mass value="0.09614332" />
            <inertia ixx="0.00004332" ixy="-0.00000017" ixz="-0.00000349" iyy="0.00004756" iyz="0.00000055" izz="0.00002008" />
        </inertial>
        <visual>
            <origin rpy="0 0 0" xyz="0 0 0" />
            <geometry>
                <mesh filename="package://dx_robot/description/meshes/dx_e3r3_finger/F0_proximal.STL" />
            </geometry>
            <material name="">
                <color rgba="0.75294 0.75294 0.75294 1" />
            </material>
        </visual>
        <collision>
            <origin rpy="0 0 0" xyz="0 0 0" />
            <geometry>
                <mesh filename="package://dx_robot/description/meshes/dx_e3r3_finger/collision/F0_proximal.STL" />
            </geometry>
        </collision>
    </link>
    <joint name="h0_F1_J1" type="revolute">
        <origin rpy="0 0 0" xyz="0 0.0765883365730207 0.0299999999999999" />
        <parent link="h0_F1_J0_link" />
        <child link="h0_F1_proximal" />
        <axis xyz="1 0 0" />
        <limit effort="1.2" lower="-1.396" upper="0.785" velocity="2" />
    </joint>
    <link name="h0_F1_middle">
        <inertial>
            <origin rpy="0 0 0" xyz="-0.00026744 -0.00004338 0.01669764" />
            <mass value="0.05585897" />
            <inertia ixx="0.00001447" ixy="-0.00000005" ixz="-0.00000004" iyy="0.00001686" iyz="-0.00000007" izz="0.00000973" />
        </inertial>
        <visual>
            <origin rpy="0 0 0" xyz="0 0 0" />
            <geometry>
                <mesh filename="package://dx_robot/description/meshes/dx_e3r3_finger/F0_middle.STL" />
            </geometry>
            <material name="">
                <color rgba="0.75294 0.75294 0.75294 1" />
            </material>
        </visual>
        <collision>
            <origin rpy="0 0 0" xyz="0 0 0" />
            <geometry>
                <mesh filename="package://dx_robot/description/meshes/dx_e3r3_finger/collision/F0_middle.STL" />
            </geometry>
        </collision>
    </link>
    <joint name="h0_F1_J2" type="revolute">
        <origin rpy="0 0 0" xyz="0 0 0.05" />
        <parent link="h0_F1_proximal" />
        <child link="h0_F1_middle" />
        <axis xyz="1 0 0" />
        <limit effort="0.7" lower="0" upper="1.396" velocity="2" />
    </joint>
    <link name="h0_F1_distal">
        <inertial>
            <origin rpy="0 0 0" xyz="0.00084325 0.00164346 0.01482169" />
            <mass value="0.02766365" />
            <inertia ixx="0.0000051" ixy="0" ixz="0.00000028" iyy="0.00000506" iyz="-0.00000034" izz="0.00000198" />
        </inertial>
        <visual>
            <origin rpy="0 0 0" xyz="0 0 0" />
            <geometry>
                <mesh filename="package://dx_robot/description/meshes/dx_e3r3_finger/F0_distal.STL" />
            </geometry>
            <material name="">
                <color rgba="0.75294 0.75294 0.75294 1" />
            </material>
        </visual>
        <collision>
            <origin rpy="0 0 0" xyz="0 0 0" />
            <geometry>
                <mesh filename="package://dx_robot/description/meshes/dx_e3r3_finger/collision/F0_distal.STL" />
            </geometry>
        </collision>
    </link>
    <joint name="h0_F1_J3" type="revolute">
        <origin rpy="0 0 0" xyz="0 0 0.035" />
        <parent link="h0_F1_middle" />
        <child link="h0_F1_distal" />
        <axis xyz="1 0 0" />
        <limit effort="0.35" lower="-0.523" upper="1.485" velocity="0.2" />
    </joint>
    <link name="h0_F1_tip" />
    <joint name="h0_F1_distal_tip" type="fixed">
        <parent link="h0_F1_distal" />
        <child link="h0_F1_tip" />
        <origin rpy="0 0 0" xyz="0 0.003 0.033" />
    </joint>
    <!-- These transmissions are wrongly configured and fail to be loaded by the real robot -->
    <!-- We still need to define them in order to be able to launch the robot in simulation -->
    <transmission name="trans_h0_F1_J0">
        <type>UnusedTransmission</type>
        <joint name="h0_F1_J0">
            <hardwareInterface>hardware_interface/EffortJointInterface</hardwareInterface>
        </joint>
        <actuator name="h0_F1_J0_motor">
            <!-- <hardwareInterface>hardware_interface/EffortJointInterface</hardwareInterface> -->
            <mechanicalReduction>1</mechanicalReduction>
        </actuator>
    </transmission>
    <transmission name="trans_h0_F1_J1">
        <type>UnusedTransmission</type>
        <joint name="h0_F1_J1">
            <hardwareInterface>hardware_interface/EffortJointInterface</hardwareInterface>
        </joint>
        <actuator name="h0_F1_J1_motor">
            <!-- <hardwareInterface>hardware_interface/EffortJointInterface</hardwareInterface> -->
            <mechanicalReduction>1</mechanicalReduction>
        </actuator>
    </transmission>
    <transmission name="trans_h0_F1_J2">
        <type>UnusedTransmission</type>
        <joint name="h0_F1_J2">
            <hardwareInterface>hardware_interface/EffortJointInterface</hardwareInterface>
        </joint>
        <actuator name="h0_F1_J2_motor">
            <!-- <hardwareInterface>hardware_interface/EffortJointInterface</hardwareInterface> -->
            <mechanicalReduction>1</mechanicalReduction>
        </actuator>
    </transmission>
    <transmission name="trans_h0_F1_J3">
        <type>UnusedTransmission</type>
        <joint name="h0_F1_J3">
            <hardwareInterface>hardware_interface/EffortJointInterface</hardwareInterface>
        </joint>
        <actuator name="h0_F1_J3_motor">
            <!-- <hardwareInterface>hardware_interface/EffortJointInterface</hardwareInterface> -->
            <mechanicalReduction>1</mechanicalReduction>
        </actuator>
    </transmission>
    <joint name="h0_world_joint_F2" type="fixed">
        <origin rpy="-1.5707 0 2.8159" xyz="-0.0384 -0.02870 0.017" />
        <parent link="h0_hand_base" />
        <child link="h0_F2_base" />
    </joint>
    <link name="h0_F2_base">
        <inertial>
            <origin rpy="0 0 0" xyz="0.00004454 0.00736569 0.08093736" />
            <mass value="0.89937782" />
            <inertia ixx="0.00186283" ixy="-0.00000176" ixz="-0.00000296" iyy="0.00181365" iyz="0.00004212" izz="0.00058221" />
        </inertial>
        <visual>
            <origin rpy="1.5707 0 0" xyz="0 0 0" />
            <geometry>
                <mesh filename="package://dx_robot/description/meshes/dx_e3r3_finger/F0_base.STL" />
            </geometry>
            <material name="">
                <color rgba="0.75294 0.75294 0.75294 1" />
            </material>
        </visual>
        <collision>
            <origin rpy="1.5707 0 0" xyz="0 0 0" />
            <geometry>
                <mesh filename="package://dx_robot/description/meshes/dx_e3r3_finger/collision/F0_base.STL" />
            </geometry>
        </collision>
    </link>
    <link name="h0_F2_J0_link">
        <inertial>
            <origin rpy="0 0 0" xyz="-0.00017293 -0.01537184 0.00956679" />
            <mass value="0.13077995" />
            <inertia ixx="0.00005895" ixy="0.00000007" ixz="0.00000064" iyy="0.00004702" iyz="-0.00000971" izz="0.00003911" />
        </inertial>
        <visual>
            <origin rpy="0 0 0" xyz="0 0.077 0" />
            <geometry>
                <mesh filename="package://dx_robot/description/meshes/dx_e3r3_finger/F0_J0_link.STL" />
            </geometry>
            <material name="">
                <color rgba="0.75294 0.75294 0.75294 1" />
            </material>
        </visual>
        <collision>
            <origin rpy="0 0 0" xyz="0 0.077 0" />
            <geometry>
                <mesh filename="package://dx_robot/description/meshes/dx_e3r3_finger/collision/F0_J0_link.STL" />
            </geometry>
        </collision>
    </link>
    <joint name="h0_F2_J0" type="revolute">
        <origin rpy="2.0944 0 0" xyz="0 -0.14073 -0.051327" />
        <parent link="h0_F2_base" />
        <child link="h0_F2_J0_link" />
        <axis xyz="0 -1 0" />
        <limit effort="1.5" lower="-0.8727" upper="0.8727" velocity="2" />
    </joint>
    <link name="h0_F2_proximal">
        <inertial>
            <origin rpy="0 0 0" xyz="-0.00020256 0.0024322 0.02375091" />
            <mass value="0.09614332" />
            <inertia ixx="0.00004332" ixy="-0.00000017" ixz="-0.00000349" iyy="0.00004756" iyz="0.00000055" izz="0.00002008" />
        </inertial>
        <visual>
            <origin rpy="0 0 0" xyz="0 0 0" />
            <geometry>
                <mesh filename="package://dx_robot/description/meshes/dx_e3r3_finger/F0_proximal.STL" />
            </geometry>
            <material name="">
                <color rgba="0.75294 0.75294 0.75294 1" />
            </material>
        </visual>
        <collision>
            <origin rpy="0 0 0" xyz="0 0 0" />
            <geometry>
                <mesh filename="package://dx_robot/description/meshes/dx_e3r3_finger/collision/F0_proximal.STL" />
            </geometry>
        </collision>
    </link>
    <joint name="h0_F2_J1" type="revolute">
        <origin rpy="0 0 0" xyz="0 0.0765883365730207 0.0299999999999999" />
        <parent link="h0_F2_J0_link" />
        <child link="h0_F2_proximal" />
        <axis xyz="1 0 0" />
        <limit effort="1.2" lower="-1.396" upper="0.785" velocity="2" />
    </joint>
    <link name="h0_F2_middle">
        <inertial>
            <origin rpy="0 0 0" xyz="-0.00026744 -0.00004338 0.01669764" />
            <mass value="0.05585897" />
            <inertia ixx="0.00001447" ixy="-0.00000005" ixz="-0.00000004" iyy="0.00001686" iyz="-0.00000007" izz="0.00000973" />
        </inertial>
        <visual>
            <origin rpy="0 0 0" xyz="0 0 0" />
            <geometry>
                <mesh filename="package://dx_robot/description/meshes/dx_e3r3_finger/F0_middle.STL" />
            </geometry>
            <material name="">
                <color rgba="0.75294 0.75294 0.75294 1" />
            </material>
        </visual>
        <collision>
            <origin rpy="0 0 0" xyz="0 0 0" />
            <geometry>
                <mesh filename="package://dx_robot/description/meshes/dx_e3r3_finger/collision/F0_middle.STL" />
            </geometry>
        </collision>
    </link>
    <joint name="h0_F2_J2" type="revolute">
        <origin rpy="0 0 0" xyz="0 0 0.05" />
        <parent link="h0_F2_proximal" />
        <child link="h0_F2_middle" />
        <axis xyz="1 0 0" />
        <limit effort="0.7" lower="0" upper="1.396" velocity="2" />
    </joint>
    <link name="h0_F2_distal">
        <inertial>
            <origin rpy="0 0 0" xyz="0.00084325 0.00164346 0.01482169" />
            <mass value="0.02766365" />
            <inertia ixx="0.0000051" ixy="0" ixz="0.00000028" iyy="0.00000506" iyz="-0.00000034" izz="0.00000198" />
        </inertial>
        <visual>
            <origin rpy="0 0 0" xyz="0 0 0" />
            <geometry>
                <mesh filename="package://dx_robot/description/meshes/dx_e3r3_finger/F0_distal.STL" />
            </geometry>
            <material name="">
                <color rgba="0.75294 0.75294 0.75294 1" />
            </material>
        </visual>
        <collision>
            <origin rpy="0 0 0" xyz="0 0 0" />
            <geometry>
                <mesh filename="package://dx_robot/description/meshes/dx_e3r3_finger/collision/F0_distal.STL" />
            </geometry>
        </collision>
    </link>
    <joint name="h0_F2_J3" type="revolute">
        <origin rpy="0 0 0" xyz="0 0 0.035" />
        <parent link="h0_F2_middle" />
        <child link="h0_F2_distal" />
        <axis xyz="1 0 0" />
        <limit effort="0.35" lower="-0.523" upper="1.485" velocity="0.2" />
    </joint>
    <link name="h0_F2_tip" />
    <joint name="h0_F2_distal_tip" type="fixed">
        <parent link="h0_F2_distal" />
        <child link="h0_F2_tip" />
        <origin rpy="0 0 0" xyz="0 0.003 0.033" />
    </joint>
    <!-- These transmissions are wrongly configured and fail to be loaded by the real robot -->
    <!-- We still need to define them in order to be able to launch the robot in simulation -->
    <transmission name="trans_h0_F2_J0">
        <type>UnusedTransmission</type>
        <joint name="h0_F2_J0">
            <hardwareInterface>hardware_interface/EffortJointInterface</hardwareInterface>
        </joint>
        <actuator name="h0_F2_J0_motor">
            <!-- <hardwareInterface>hardware_interface/EffortJointInterface</hardwareInterface> -->
            <mechanicalReduction>1</mechanicalReduction>
        </actuator>
    </transmission>
    <transmission name="trans_h0_F2_J1">
        <type>UnusedTransmission</type>
        <joint name="h0_F2_J1">
            <hardwareInterface>hardware_interface/EffortJointInterface</hardwareInterface>
        </joint>
        <actuator name="h0_F2_J1_motor">
            <!-- <hardwareInterface>hardware_interface/EffortJointInterface</hardwareInterface> -->
            <mechanicalReduction>1</mechanicalReduction>
        </actuator>
    </transmission>
    <transmission name="trans_h0_F2_J2">
        <type>UnusedTransmission</type>
        <joint name="h0_F2_J2">
            <hardwareInterface>hardware_interface/EffortJointInterface</hardwareInterface>
        </joint>
        <actuator name="h0_F2_J2_motor">
            <!-- <hardwareInterface>hardware_interface/EffortJointInterface</hardwareInterface> -->
            <mechanicalReduction>1</mechanicalReduction>
        </actuator>
    </transmission>
    <transmission name="trans_h0_F2_J3">
        <type>UnusedTransmission</type>
        <joint name="h0_F2_J3">
            <hardwareInterface>hardware_interface/EffortJointInterface</hardwareInterface>
        </joint>
        <actuator name="h0_F2_J3_motor">
            <!-- <hardwareInterface>hardware_interface/EffortJointInterface</hardwareInterface> -->
            <mechanicalReduction>1</mechanicalReduction>
        </actuator>
    </transmission>
    <!-- TODO Do something for the mounting plate (as it is shown below for hand E)
  <xacro:sr_hand side="$(arg side)" hand_type="$(arg hand_type)" hand_version="$(arg hand_version)"
                  fingers="$(arg fingers)" tip_sensors="$(arg tip_sensors)" mid_sensors="$(arg mid_sensors)"
                  prox_sensors="$(arg prox_sensors)" palm_sensor="$(arg palm_sensor)" mounting_plate="true"/> -->
    <joint name="world_joint" type="fixed">
        <parent link="world" />
        <child link="a0_base_link" />
        <origin rpy="0.0 0.0 0.0" xyz="0.0 0.0 0.1" />
    </joint>
    <joint name="a0_arm_to_hand" type="fixed">
        <parent link="a0_flange" />
        <child link="h0_hand_base" />
        <!-- TODO check if the rotation in this fixed joint is correct (the one below is OK for hand E) -->
        <origin rpy="1.5707963267948966 3.141592653589793 1.5707963267948966" xyz="0.0 0.0 0.0" />
    </joint>
    <gazebo>
        <plugin filename="libgazebo_ros_control.so" name="gazebo_ros_control">
            <!--robotSimType>gazebo_ros_control/DefaultRobotHWSim</robotSimType-->
            <robotNamespace>arm_0</robotNamespace>
            <robotParam>a0_robot_description</robotParam>
        </plugin>
    </gazebo>
    <gazebo>
        <plugin filename="libgazebo_ros_control.so" name="gazebo_ros_control">
            <!--robotSimType>gazebo_ros_control/DefaultRobotHWSim</robotSimType-->
            <robotNamespace>hand_0</robotNamespace>
            <robotParam>h0_robot_description</robotParam>
        </plugin>
    </gazebo>
    <transmission name="trans_h0_F0_J0">
        <type>transmission_interface/SimpleTransmission</type>
        <joint name="h0_F0_J0">
            <hardwareInterface>hardware_interface/EffortJointInterface</hardwareInterface>
        </joint>
        <actuator name="h0_F0_J0_motor">
            <hardwareInterface>hardware_interface/EffortJointInterface</hardwareInterface>
            <mechanicalReduction>1</mechanicalReduction>
        </actuator>
    </transmission>
    <transmission name="trans_h0_F0_J1">
        <type>transmission_interface/SimpleTransmission</type>
        <joint name="h0_F0_J1">
            <hardwareInterface>hardware_interface/EffortJointInterface</hardwareInterface>
        </joint>
        <actuator name="h0_F0_J1_motor">
            <hardwareInterface>hardware_interface/EffortJointInterface</hardwareInterface>
            <mechanicalReduction>1</mechanicalReduction>
        </actuator>
    </transmission>
    <transmission name="trans_h0_F0_J2">
        <type>transmission_interface/SimpleTransmission</type>
        <joint name="h0_F0_J2">
            <hardwareInterface>hardware_interface/EffortJointInterface</hardwareInterface>
        </joint>
        <actuator name="h0_F0_J2_motor">
            <hardwareInterface>hardware_interface/EffortJointInterface</hardwareInterface>
            <mechanicalReduction>1</mechanicalReduction>
        </actuator>
    </transmission>
    <transmission name="trans_h0_F0_J3">
        <type>transmission_interface/SimpleTransmission</type>
        <joint name="h0_F0_J3">
            <hardwareInterface>hardware_interface/EffortJointInterface</hardwareInterface>
        </joint>
        <actuator name="h0_F0_J3_motor">
            <hardwareInterface>hardware_interface/EffortJointInterface</hardwareInterface>
            <mechanicalReduction>1</mechanicalReduction>
        </actuator>
    </transmission>
    <transmission name="trans_h0_F1_J0">
        <type>transmission_interface/SimpleTransmission</type>
        <joint name="h0_F1_J0">
            <hardwareInterface>hardware_interface/EffortJointInterface</hardwareInterface>
        </joint>
        <actuator name="h0_F1_J0_motor">
            <hardwareInterface>hardware_interface/EffortJointInterface</hardwareInterface>
            <mechanicalReduction>1</mechanicalReduction>
        </actuator>
    </transmission>
    <transmission name="trans_h0_F1_J1">
        <type>transmission_interface/SimpleTransmission</type>
        <joint name="h0_F1_J1">
            <hardwareInterface>hardware_interface/EffortJointInterface</hardwareInterface>
        </joint>
        <actuator name="h0_F1_J1_motor">
            <hardwareInterface>hardware_interface/EffortJointInterface</hardwareInterface>
            <mechanicalReduction>1</mechanicalReduction>
        </actuator>
    </transmission>
    <transmission name="trans_h0_F1_J2">
        <type>transmission_interface/SimpleTransmission</type>
        <joint name="h0_F1_J2">
            <hardwareInterface>hardware_interface/EffortJointInterface</hardwareInterface>
        </joint>
        <actuator name="h0_F1_J2_motor">
            <hardwareInterface>hardware_interface/EffortJointInterface</hardwareInterface>
            <mechanicalReduction>1</mechanicalReduction>
        </actuator>
    </transmission>
    <transmission name="trans_h0_F1_J3">
        <type>transmission_interface/SimpleTransmission</type>
        <joint name="h0_F1_J3">
            <hardwareInterface>hardware_interface/EffortJointInterface</hardwareInterface>
        </joint>
        <actuator name="h0_F1_J3_motor">
            <hardwareInterface>hardware_interface/EffortJointInterface</hardwareInterface>
            <mechanicalReduction>1</mechanicalReduction>
        </actuator>
    </transmission>
    <transmission name="trans_h0_F2_J0">
        <type>transmission_interface/SimpleTransmission</type>
        <joint name="h0_F2_J0">
            <hardwareInterface>hardware_interface/EffortJointInterface</hardwareInterface>
        </joint>
        <actuator name="h0_F2_J0_motor">
            <hardwareInterface>hardware_interface/EffortJointInterface</hardwareInterface>
            <mechanicalReduction>1</mechanicalReduction>
        </actuator>
    </transmission>
    <transmission name="trans_h0_F2_J1">
        <type>transmission_interface/SimpleTransmission</type>
        <joint name="h0_F2_J1">
            <hardwareInterface>hardware_interface/EffortJointInterface</hardwareInterface>
        </joint>
        <actuator name="h0_F2_J1_motor">
            <hardwareInterface>hardware_interface/EffortJointInterface</hardwareInterface>
            <mechanicalReduction>1</mechanicalReduction>
        </actuator>
    </transmission>
    <transmission name="trans_h0_F2_J2">
        <type>transmission_interface/SimpleTransmission</type>
        <joint name="h0_F2_J2">
            <hardwareInterface>hardware_interface/EffortJointInterface</hardwareInterface>
        </joint>
        <actuator name="h0_F2_J2_motor">
            <hardwareInterface>hardware_interface/EffortJointInterface</hardwareInterface>
            <mechanicalReduction>1</mechanicalReduction>
        </actuator>
    </transmission>
    <transmission name="trans_h0_F2_J3">
        <type>transmission_interface/SimpleTransmission</type>
        <joint name="h0_F2_J3">
            <hardwareInterface>hardware_interface/EffortJointInterface</hardwareInterface>
        </joint>
        <actuator name="h0_F2_J3_motor">
            <hardwareInterface>hardware_interface/EffortJointInterface</hardwareInterface>
            <mechanicalReduction>1</mechanicalReduction>
        </actuator>
    </transmission>
</robot>
