<?xml version="1.0" ?>
<!-- =================================================================================== -->
<!-- |    This document was autogenerated by xacro from /home/user/projects/shadow_robot/base/src/dx_system/dx_launch/description/0x02000105.urdf.xacro | -->
<!-- |    EDITING THIS FILE BY HAND IS NOT RECOMMENDED                                 | -->
<!-- =================================================================================== -->
<!--
 Copyright (C) 2024-2025 Shadow Robot Company Ltd - All Rights Reserved. Proprietary and Confidential.
 Unauthorized copying of the content in this file, via any medium is strictly prohibited.
-->
<robot name="e3_r3_hand">
    <link name="world" />
    <joint name="h0_world_joint" type="fixed">
        <parent link="world" />
        <child link="h0_hand_base" />
    </joint>
    <link name="h0_hand_base">
        <inertial>
            <origin rpy="0 0 0" xyz="0.00024269 0.0064896 0.05011689" />
            <mass value="0.53506724" />
            <inertia ixx="0.00235606" ixy="-0.00000318" ixz="0.00001251" iyy="0.00262644" iyz="-0.00010584" izz="0.00095084" />
        </inertial>
        <visual>
            <origin rpy="0 0 0" xyz="0 0 0" />
            <geometry>
                <mesh filename="package://dx_robot/description/meshes/dx_e3r3_finger/H_Base.STL" />
            </geometry>
            <material name="">
                <color rgba="0.898039215686275 0.917647058823529 0.929411764705882 1" />
            </material>
        </visual>
        <collision>
            <origin rpy="0 0 0" xyz="0 0 0" />
            <geometry>
                <mesh filename="package://dx_robot/description/meshes/dx_e3r3_finger/collision/Hand_Base.STL" />
            </geometry>
        </collision>
    </link>
    <!-- Create a virtual end effector link that will be useful for arm IK -->
    <link name="h0_end_effector" />
    <joint name="h0_ee_fixed_joint" type="fixed">
        <parent link="h0_hand_base" />
        <child link="h0_end_effector" />
        <origin rpy="0.0 0.0 0.0" xyz="0.0 0.0 0.25" />
    </joint>
    <joint name="h0_world_joint_F0" type="fixed">
        <origin rpy="-1.5707 0 0" xyz="0 0.05 0.017" />
        <parent link="h0_hand_base" />
        <child link="h0_F0_base" />
    </joint>
    <link name="h0_F0_base">
        <inertial>
            <origin rpy="0 0 0" xyz="0.00004454 0.00736569 0.08093736" />
            <mass value="0.89937782" />
            <inertia ixx="0.00186283" ixy="-0.00000176" ixz="-0.00000296" iyy="0.00181365" iyz="0.00004212" izz="0.00058221" />
        </inertial>
        <visual>
            <origin rpy="1.5707 0 0" xyz="0 0 0" />
            <geometry>
                <mesh filename="package://dx_robot/description/meshes/dx_e3r3_finger/F0_base.STL" />
            </geometry>
            <material name="">
                <color rgba="0.75294 0.75294 0.75294 1" />
            </material>
        </visual>
        <collision>
            <origin rpy="1.5707 0 0" xyz="0 0 0" />
            <geometry>
                <mesh filename="package://dx_robot/description/meshes/dx_e3r3_finger/collision/F0_base.STL" />
            </geometry>
        </collision>
    </link>
    <link name="h0_F0_J0_link">
        <inertial>
            <origin rpy="0 0 0" xyz="-0.00017293 -0.01537184 0.00956679" />
            <mass value="0.13077995" />
            <inertia ixx="0.00005895" ixy="0.00000007" ixz="0.00000064" iyy="0.00004702" iyz="-0.00000971" izz="0.00003911" />
        </inertial>
        <visual>
            <origin rpy="0 0 0" xyz="0 0.077 0" />
            <geometry>
                <mesh filename="package://dx_robot/description/meshes/dx_e3r3_finger/F0_J0_link.STL" />
            </geometry>
            <material name="">
                <color rgba="0.75294 0.75294 0.75294 1" />
            </material>
        </visual>
        <collision>
            <origin rpy="0 0 0" xyz="0 0.077 0" />
            <geometry>
                <mesh filename="package://dx_robot/description/meshes/dx_e3r3_finger/collision/F0_J0_link.STL" />
            </geometry>
        </collision>
    </link>
    <joint name="h0_F0_J0" type="revolute">
        <origin rpy="2.0944 0 0" xyz="0 -0.14073 -0.051327" />
        <parent link="h0_F0_base" />
        <child link="h0_F0_J0_link" />
        <axis xyz="0 -1 0" />
        <limit effort="1.5" lower="-0.8727" upper="0.8727" velocity="3.1415" />
        <dynamics friction="0.001" />
    </joint>
    <link name="h0_F0_proximal">
        <inertial>
            <origin rpy="0 0 0" xyz="-0.00020256 0.0024322 0.02375091" />
            <mass value="0.09614332" />
            <inertia ixx="0.00004332" ixy="-0.00000017" ixz="-0.00000349" iyy="0.00004756" iyz="0.00000055" izz="0.00002008" />
        </inertial>
        <visual>
            <origin rpy="0 0 0" xyz="0 0 0" />
            <geometry>
                <mesh filename="package://dx_robot/description/meshes/dx_e3r3_finger/F0_proximal.STL" />
            </geometry>
            <material name="">
                <color rgba="0.75294 0.75294 0.75294 1" />
            </material>
        </visual>
        <collision>
            <origin rpy="0 0 0" xyz="0 0 0" />
            <geometry>
                <mesh filename="package://dx_robot/description/meshes/dx_e3r3_finger/collision/F0_proximal.STL" />
            </geometry>
        </collision>
    </link>
    <joint name="h0_F0_J1" type="revolute">
        <origin rpy="0 0 0" xyz="0 0.0765883365730207 0.0299999999999999" />
        <parent link="h0_F0_J0_link" />
        <child link="h0_F0_proximal" />
        <axis xyz="1 0 0" />
        <limit effort="1.2" lower="-1.396" upper="0.785" velocity="3.1415" />
        <dynamics friction="0.001" />
    </joint>
    <link name="h0_F0_middle">
        <inertial>
            <origin rpy="0 0 0" xyz="-0.00026744 -0.00004338 0.01669764" />
            <mass value="0.05585897" />
            <inertia ixx="0.00001447" ixy="-0.00000005" ixz="-0.00000004" iyy="0.00001686" iyz="-0.00000007" izz="0.00000973" />
        </inertial>
        <visual>
            <origin rpy="0 0 0" xyz="0 0 0" />
            <geometry>
                <mesh filename="package://dx_robot/description/meshes/dx_e3r3_finger/F0_middle.STL" />
            </geometry>
            <material name="">
                <color rgba="0.75294 0.75294 0.75294 1" />
            </material>
        </visual>
        <collision>
            <origin rpy="0 0 0" xyz="0 0 0" />
            <geometry>
                <mesh filename="package://dx_robot/description/meshes/dx_e3r3_finger/collision/F0_middle.STL" />
            </geometry>
        </collision>
    </link>
    <joint name="h0_F0_J2" type="revolute">
        <origin rpy="0 0 0" xyz="0 0 0.05" />
        <parent link="h0_F0_proximal" />
        <child link="h0_F0_middle" />
        <axis xyz="1 0 0" />
        <limit effort="0.7" lower="0" upper="1.396" velocity="3.1415" />
        <dynamics friction="0.001" />
    </joint>
    <link name="h0_F0_distal">
        <inertial>
            <origin rpy="0 0 0" xyz="0.00084325 0.00164346 0.01482169" />
            <mass value="0.02766365" />
            <inertia ixx="0.0000051" ixy="0" ixz="0.00000028" iyy="0.00000506" iyz="-0.00000034" izz="0.00000198" />
        </inertial>
        <visual>
            <origin rpy="0 0 0" xyz="0 0 0" />
            <geometry>
                <mesh filename="package://dx_robot/description/meshes/dx_e3r3_finger/F0_distal.STL" />
            </geometry>
            <material name="">
                <color rgba="0.75294 0.75294 0.75294 1" />
            </material>
        </visual>
        <collision>
            <origin rpy="0 0 0" xyz="0 0 0" />
            <geometry>
                <mesh filename="package://dx_robot/description/meshes/dx_e3r3_finger/collision/F0_distal.STL" />
            </geometry>
        </collision>
    </link>
    <joint name="h0_F0_J3" type="revolute">
        <origin rpy="0 0 0" xyz="0 0 0.035" />
        <parent link="h0_F0_middle" />
        <child link="h0_F0_distal" />
        <axis xyz="1 0 0" />
        <limit effort="0.35" lower="-0.523" upper="1.485" velocity="3.1415" />
        <dynamics friction="0.001" />
    </joint>
    <link name="h0_F0_tip" />
    <joint name="h0_F0_distal_tip" type="fixed">
        <parent link="h0_F0_distal" />
        <child link="h0_F0_tip" />
        <origin rpy="0 0 0" xyz="0 0.003 0.033" />
    </joint>
    <!-- These transmissions are wrongly configured and fail to be loaded by the real robot -->
    <!-- We still need to define them in order to be able to launch the robot in simulation -->
    <transmission name="trans_h0_F0_J0">
        <type>UnusedTransmission</type>
        <joint name="h0_F0_J0">
            <hardwareInterface>hardware_interface/EffortJointInterface</hardwareInterface>
        </joint>
        <actuator name="h0_F0_J0_motor">
            <!-- <hardwareInterface>hardware_interface/EffortJointInterface</hardwareInterface> -->
            <mechanicalReduction>1</mechanicalReduction>
        </actuator>
    </transmission>
    <transmission name="trans_h0_F0_J1">
        <type>UnusedTransmission</type>
        <joint name="h0_F0_J1">
            <hardwareInterface>hardware_interface/EffortJointInterface</hardwareInterface>
        </joint>
        <actuator name="h0_F0_J1_motor">
            <!-- <hardwareInterface>hardware_interface/EffortJointInterface</hardwareInterface> -->
            <mechanicalReduction>1</mechanicalReduction>
        </actuator>
    </transmission>
    <transmission name="trans_h0_F0_J2">
        <type>UnusedTransmission</type>
        <joint name="h0_F0_J2">
            <hardwareInterface>hardware_interface/EffortJointInterface</hardwareInterface>
        </joint>
        <actuator name="h0_F0_J2_motor">
            <!-- <hardwareInterface>hardware_interface/EffortJointInterface</hardwareInterface> -->
            <mechanicalReduction>1</mechanicalReduction>
        </actuator>
    </transmission>
    <transmission name="trans_h0_F0_J3">
        <type>UnusedTransmission</type>
        <joint name="h0_F0_J3">
            <hardwareInterface>hardware_interface/EffortJointInterface</hardwareInterface>
        </joint>
        <actuator name="h0_F0_J3_motor">
            <!-- <hardwareInterface>hardware_interface/EffortJointInterface</hardwareInterface> -->
            <mechanicalReduction>1</mechanicalReduction>
        </actuator>
    </transmission>
    <joint name="h0_world_joint_F1" type="fixed">
        <origin rpy="-1.5707 0 -2.8159" xyz="0.0384 -0.0287 0.017" />
        <parent link="h0_hand_base" />
        <child link="h0_F1_base" />
    </joint>
    <link name="h0_F1_base">
        <inertial>
            <origin rpy="0 0 0" xyz="0.00004454 0.00736569 0.08093736" />
            <mass value="0.89937782" />
            <inertia ixx="0.00186283" ixy="-0.00000176" ixz="-0.00000296" iyy="0.00181365" iyz="0.00004212" izz="0.00058221" />
        </inertial>
        <visual>
            <origin rpy="1.5707 0 0" xyz="0 0 0" />
            <geometry>
                <mesh filename="package://dx_robot/description/meshes/dx_e3r3_finger/F0_base.STL" />
            </geometry>
            <material name="">
                <color rgba="0.75294 0.75294 0.75294 1" />
            </material>
        </visual>
        <collision>
            <origin rpy="1.5707 0 0" xyz="0 0 0" />
            <geometry>
                <mesh filename="package://dx_robot/description/meshes/dx_e3r3_finger/collision/F0_base.STL" />
            </geometry>
        </collision>
    </link>
    <link name="h0_F1_J0_link">
        <inertial>
            <origin rpy="0 0 0" xyz="-0.00017293 -0.01537184 0.00956679" />
            <mass value="0.13077995" />
            <inertia ixx="0.00005895" ixy="0.00000007" ixz="0.00000064" iyy="0.00004702" iyz="-0.00000971" izz="0.00003911" />
        </inertial>
        <visual>
            <origin rpy="0 0 0" xyz="0 0.077 0" />
            <geometry>
                <mesh filename="package://dx_robot/description/meshes/dx_e3r3_finger/F0_J0_link.STL" />
            </geometry>
            <material name="">
                <color rgba="0.75294 0.75294 0.75294 1" />
            </material>
        </visual>
        <collision>
            <origin rpy="0 0 0" xyz="0 0.077 0" />
            <geometry>
                <mesh filename="package://dx_robot/description/meshes/dx_e3r3_finger/collision/F0_J0_link.STL" />
            </geometry>
        </collision>
    </link>
    <joint name="h0_F1_J0" type="revolute">
        <origin rpy="2.0944 0 0" xyz="0 -0.14073 -0.051327" />
        <parent link="h0_F1_base" />
        <child link="h0_F1_J0_link" />
        <axis xyz="0 -1 0" />
        <limit effort="1.5" lower="-0.8727" upper="0.8727" velocity="3.1415" />
        <dynamics friction="0.001" />
    </joint>
    <link name="h0_F1_proximal">
        <inertial>
            <origin rpy="0 0 0" xyz="-0.00020256 0.0024322 0.02375091" />
            <mass value="0.09614332" />
            <inertia ixx="0.00004332" ixy="-0.00000017" ixz="-0.00000349" iyy="0.00004756" iyz="0.00000055" izz="0.00002008" />
        </inertial>
        <visual>
            <origin rpy="0 0 0" xyz="0 0 0" />
            <geometry>
                <mesh filename="package://dx_robot/description/meshes/dx_e3r3_finger/F0_proximal.STL" />
            </geometry>
            <material name="">
                <color rgba="0.75294 0.75294 0.75294 1" />
            </material>
        </visual>
        <collision>
            <origin rpy="0 0 0" xyz="0 0 0" />
            <geometry>
                <mesh filename="package://dx_robot/description/meshes/dx_e3r3_finger/collision/F0_proximal.STL" />
            </geometry>
        </collision>
    </link>
    <joint name="h0_F1_J1" type="revolute">
        <origin rpy="0 0 0" xyz="0 0.0765883365730207 0.0299999999999999" />
        <parent link="h0_F1_J0_link" />
        <child link="h0_F1_proximal" />
        <axis xyz="1 0 0" />
        <limit effort="1.2" lower="-1.396" upper="0.785" velocity="3.1415" />
        <dynamics friction="0.001" />
    </joint>
    <link name="h0_F1_middle">
        <inertial>
            <origin rpy="0 0 0" xyz="-0.00026744 -0.00004338 0.01669764" />
            <mass value="0.05585897" />
            <inertia ixx="0.00001447" ixy="-0.00000005" ixz="-0.00000004" iyy="0.00001686" iyz="-0.00000007" izz="0.00000973" />
        </inertial>
        <visual>
            <origin rpy="0 0 0" xyz="0 0 0" />
            <geometry>
                <mesh filename="package://dx_robot/description/meshes/dx_e3r3_finger/F0_middle.STL" />
            </geometry>
            <material name="">
                <color rgba="0.75294 0.75294 0.75294 1" />
            </material>
        </visual>
        <collision>
            <origin rpy="0 0 0" xyz="0 0 0" />
            <geometry>
                <mesh filename="package://dx_robot/description/meshes/dx_e3r3_finger/collision/F0_middle.STL" />
            </geometry>
        </collision>
    </link>
    <joint name="h0_F1_J2" type="revolute">
        <origin rpy="0 0 0" xyz="0 0 0.05" />
        <parent link="h0_F1_proximal" />
        <child link="h0_F1_middle" />
        <axis xyz="1 0 0" />
        <limit effort="0.7" lower="0" upper="1.396" velocity="3.1415" />
        <dynamics friction="0.001" />
    </joint>
    <link name="h0_F1_distal">
        <inertial>
            <origin rpy="0 0 0" xyz="0.00084325 0.00164346 0.01482169" />
            <mass value="0.02766365" />
            <inertia ixx="0.0000051" ixy="0" ixz="0.00000028" iyy="0.00000506" iyz="-0.00000034" izz="0.00000198" />
        </inertial>
        <visual>
            <origin rpy="0 0 0" xyz="0 0 0" />
            <geometry>
                <mesh filename="package://dx_robot/description/meshes/dx_e3r3_finger/F0_distal.STL" />
            </geometry>
            <material name="">
                <color rgba="0.75294 0.75294 0.75294 1" />
            </material>
        </visual>
        <collision>
            <origin rpy="0 0 0" xyz="0 0 0" />
            <geometry>
                <mesh filename="package://dx_robot/description/meshes/dx_e3r3_finger/collision/F0_distal.STL" />
            </geometry>
        </collision>
    </link>
    <joint name="h0_F1_J3" type="revolute">
        <origin rpy="0 0 0" xyz="0 0 0.035" />
        <parent link="h0_F1_middle" />
        <child link="h0_F1_distal" />
        <axis xyz="1 0 0" />
        <limit effort="0.35" lower="-0.523" upper="1.485" velocity="3.1415" />
        <dynamics friction="0.001" />
    </joint>
    <link name="h0_F1_tip" />
    <joint name="h0_F1_distal_tip" type="fixed">
        <parent link="h0_F1_distal" />
        <child link="h0_F1_tip" />
        <origin rpy="0 0 0" xyz="0 0.003 0.033" />
    </joint>
    <!-- These transmissions are wrongly configured and fail to be loaded by the real robot -->
    <!-- We still need to define them in order to be able to launch the robot in simulation -->
    <transmission name="trans_h0_F1_J0">
        <type>UnusedTransmission</type>
        <joint name="h0_F1_J0">
            <hardwareInterface>hardware_interface/EffortJointInterface</hardwareInterface>
        </joint>
        <actuator name="h0_F1_J0_motor">
            <!-- <hardwareInterface>hardware_interface/EffortJointInterface</hardwareInterface> -->
            <mechanicalReduction>1</mechanicalReduction>
        </actuator>
    </transmission>
    <transmission name="trans_h0_F1_J1">
        <type>UnusedTransmission</type>
        <joint name="h0_F1_J1">
            <hardwareInterface>hardware_interface/EffortJointInterface</hardwareInterface>
        </joint>
        <actuator name="h0_F1_J1_motor">
            <!-- <hardwareInterface>hardware_interface/EffortJointInterface</hardwareInterface> -->
            <mechanicalReduction>1</mechanicalReduction>
        </actuator>
    </transmission>
    <transmission name="trans_h0_F1_J2">
        <type>UnusedTransmission</type>
        <joint name="h0_F1_J2">
            <hardwareInterface>hardware_interface/EffortJointInterface</hardwareInterface>
        </joint>
        <actuator name="h0_F1_J2_motor">
            <!-- <hardwareInterface>hardware_interface/EffortJointInterface</hardwareInterface> -->
            <mechanicalReduction>1</mechanicalReduction>
        </actuator>
    </transmission>
    <transmission name="trans_h0_F1_J3">
        <type>UnusedTransmission</type>
        <joint name="h0_F1_J3">
            <hardwareInterface>hardware_interface/EffortJointInterface</hardwareInterface>
        </joint>
        <actuator name="h0_F1_J3_motor">
            <!-- <hardwareInterface>hardware_interface/EffortJointInterface</hardwareInterface> -->
            <mechanicalReduction>1</mechanicalReduction>
        </actuator>
    </transmission>
    <joint name="h0_world_joint_F2" type="fixed">
        <origin rpy="-1.5707 0 2.8159" xyz="-0.0384 -0.02870 0.017" />
        <parent link="h0_hand_base" />
        <child link="h0_F2_base" />
    </joint>
    <link name="h0_F2_base">
        <inertial>
            <origin rpy="0 0 0" xyz="0.00004454 0.00736569 0.08093736" />
            <mass value="0.89937782" />
            <inertia ixx="0.00186283" ixy="-0.00000176" ixz="-0.00000296" iyy="0.00181365" iyz="0.00004212" izz="0.00058221" />
        </inertial>
        <visual>
            <origin rpy="1.5707 0 0" xyz="0 0 0" />
            <geometry>
                <mesh filename="package://dx_robot/description/meshes/dx_e3r3_finger/F0_base.STL" />
            </geometry>
            <material name="">
                <color rgba="0.75294 0.75294 0.75294 1" />
            </material>
        </visual>
        <collision>
            <origin rpy="1.5707 0 0" xyz="0 0 0" />
            <geometry>
                <mesh filename="package://dx_robot/description/meshes/dx_e3r3_finger/collision/F0_base.STL" />
            </geometry>
        </collision>
    </link>
    <link name="h0_F2_J0_link">
        <inertial>
            <origin rpy="0 0 0" xyz="-0.00017293 -0.01537184 0.00956679" />
            <mass value="0.13077995" />
            <inertia ixx="0.00005895" ixy="0.00000007" ixz="0.00000064" iyy="0.00004702" iyz="-0.00000971" izz="0.00003911" />
        </inertial>
        <visual>
            <origin rpy="0 0 0" xyz="0 0.077 0" />
            <geometry>
                <mesh filename="package://dx_robot/description/meshes/dx_e3r3_finger/F0_J0_link.STL" />
            </geometry>
            <material name="">
                <color rgba="0.75294 0.75294 0.75294 1" />
            </material>
        </visual>
        <collision>
            <origin rpy="0 0 0" xyz="0 0.077 0" />
            <geometry>
                <mesh filename="package://dx_robot/description/meshes/dx_e3r3_finger/collision/F0_J0_link.STL" />
            </geometry>
        </collision>
    </link>
    <joint name="h0_F2_J0" type="revolute">
        <origin rpy="2.0944 0 0" xyz="0 -0.14073 -0.051327" />
        <parent link="h0_F2_base" />
        <child link="h0_F2_J0_link" />
        <axis xyz="0 -1 0" />
        <limit effort="1.5" lower="-0.8727" upper="0.8727" velocity="3.1415" />
        <dynamics friction="0.001" />
    </joint>
    <link name="h0_F2_proximal">
        <inertial>
            <origin rpy="0 0 0" xyz="-0.00020256 0.0024322 0.02375091" />
            <mass value="0.09614332" />
            <inertia ixx="0.00004332" ixy="-0.00000017" ixz="-0.00000349" iyy="0.00004756" iyz="0.00000055" izz="0.00002008" />
        </inertial>
        <visual>
            <origin rpy="0 0 0" xyz="0 0 0" />
            <geometry>
                <mesh filename="package://dx_robot/description/meshes/dx_e3r3_finger/F0_proximal.STL" />
            </geometry>
            <material name="">
                <color rgba="0.75294 0.75294 0.75294 1" />
            </material>
        </visual>
        <collision>
            <origin rpy="0 0 0" xyz="0 0 0" />
            <geometry>
                <mesh filename="package://dx_robot/description/meshes/dx_e3r3_finger/collision/F0_proximal.STL" />
            </geometry>
        </collision>
    </link>
    <joint name="h0_F2_J1" type="revolute">
        <origin rpy="0 0 0" xyz="0 0.0765883365730207 0.0299999999999999" />
        <parent link="h0_F2_J0_link" />
        <child link="h0_F2_proximal" />
        <axis xyz="1 0 0" />
        <limit effort="1.2" lower="-1.396" upper="0.785" velocity="3.1415" />
        <dynamics friction="0.001" />
    </joint>
    <link name="h0_F2_middle">
        <inertial>
            <origin rpy="0 0 0" xyz="-0.00026744 -0.00004338 0.01669764" />
            <mass value="0.05585897" />
            <inertia ixx="0.00001447" ixy="-0.00000005" ixz="-0.00000004" iyy="0.00001686" iyz="-0.00000007" izz="0.00000973" />
        </inertial>
        <visual>
            <origin rpy="0 0 0" xyz="0 0 0" />
            <geometry>
                <mesh filename="package://dx_robot/description/meshes/dx_e3r3_finger/F0_middle.STL" />
            </geometry>
            <material name="">
                <color rgba="0.75294 0.75294 0.75294 1" />
            </material>
        </visual>
        <collision>
            <origin rpy="0 0 0" xyz="0 0 0" />
            <geometry>
                <mesh filename="package://dx_robot/description/meshes/dx_e3r3_finger/collision/F0_middle.STL" />
            </geometry>
        </collision>
    </link>
    <joint name="h0_F2_J2" type="revolute">
        <origin rpy="0 0 0" xyz="0 0 0.05" />
        <parent link="h0_F2_proximal" />
        <child link="h0_F2_middle" />
        <axis xyz="1 0 0" />
        <limit effort="0.7" lower="0" upper="1.396" velocity="3.1415" />
        <dynamics friction="0.001" />
    </joint>
    <link name="h0_F2_distal">
        <inertial>
            <origin rpy="0 0 0" xyz="0.00084325 0.00164346 0.01482169" />
            <mass value="0.02766365" />
            <inertia ixx="0.0000051" ixy="0" ixz="0.00000028" iyy="0.00000506" iyz="-0.00000034" izz="0.00000198" />
        </inertial>
        <visual>
            <origin rpy="0 0 0" xyz="0 0 0" />
            <geometry>
                <mesh filename="package://dx_robot/description/meshes/dx_e3r3_finger/F0_distal.STL" />
            </geometry>
            <material name="">
                <color rgba="0.75294 0.75294 0.75294 1" />
            </material>
        </visual>
        <collision>
            <origin rpy="0 0 0" xyz="0 0 0" />
            <geometry>
                <mesh filename="package://dx_robot/description/meshes/dx_e3r3_finger/collision/F0_distal.STL" />
            </geometry>
        </collision>
    </link>
    <joint name="h0_F2_J3" type="revolute">
        <origin rpy="0 0 0" xyz="0 0 0.035" />
        <parent link="h0_F2_middle" />
        <child link="h0_F2_distal" />
        <axis xyz="1 0 0" />
        <limit effort="0.35" lower="-0.523" upper="1.485" velocity="3.1415" />
        <dynamics friction="0.001" />
    </joint>
    <link name="h0_F2_tip" />
    <joint name="h0_F2_distal_tip" type="fixed">
        <parent link="h0_F2_distal" />
        <child link="h0_F2_tip" />
        <origin rpy="0 0 0" xyz="0 0.003 0.033" />
    </joint>
    <!-- These transmissions are wrongly configured and fail to be loaded by the real robot -->
    <!-- We still need to define them in order to be able to launch the robot in simulation -->
    <transmission name="trans_h0_F2_J0">
        <type>UnusedTransmission</type>
        <joint name="h0_F2_J0">
            <hardwareInterface>hardware_interface/EffortJointInterface</hardwareInterface>
        </joint>
        <actuator name="h0_F2_J0_motor">
            <!-- <hardwareInterface>hardware_interface/EffortJointInterface</hardwareInterface> -->
            <mechanicalReduction>1</mechanicalReduction>
        </actuator>
    </transmission>
    <transmission name="trans_h0_F2_J1">
        <type>UnusedTransmission</type>
        <joint name="h0_F2_J1">
            <hardwareInterface>hardware_interface/EffortJointInterface</hardwareInterface>
        </joint>
        <actuator name="h0_F2_J1_motor">
            <!-- <hardwareInterface>hardware_interface/EffortJointInterface</hardwareInterface> -->
            <mechanicalReduction>1</mechanicalReduction>
        </actuator>
    </transmission>
    <transmission name="trans_h0_F2_J2">
        <type>UnusedTransmission</type>
        <joint name="h0_F2_J2">
            <hardwareInterface>hardware_interface/EffortJointInterface</hardwareInterface>
        </joint>
        <actuator name="h0_F2_J2_motor">
            <!-- <hardwareInterface>hardware_interface/EffortJointInterface</hardwareInterface> -->
            <mechanicalReduction>1</mechanicalReduction>
        </actuator>
    </transmission>
    <transmission name="trans_h0_F2_J3">
        <type>UnusedTransmission</type>
        <joint name="h0_F2_J3">
            <hardwareInterface>hardware_interface/EffortJointInterface</hardwareInterface>
        </joint>
        <actuator name="h0_F2_J3_motor">
            <!-- <hardwareInterface>hardware_interface/EffortJointInterface</hardwareInterface> -->
            <mechanicalReduction>1</mechanicalReduction>
        </actuator>
    </transmission>
    <gazebo>
        <plugin filename="libgazebo_ros_control.so" name="gazebo_ros_control">
            <!--robotSimType>gazebo_ros_control/DefaultRobotHWSim</robotSimType-->
            <robotNamespace>right_hand</robotNamespace>
            <robotParam>h0_robot_description</robotParam>
        </plugin>
    </gazebo>
    <transmission name="trans_h0_F0_J0">
        <type>transmission_interface/SimpleTransmission</type>
        <joint name="h0_F0_J0">
            <hardwareInterface>hardware_interface/EffortJointInterface</hardwareInterface>
        </joint>
        <actuator name="h0_F0_J0_motor">
            <hardwareInterface>hardware_interface/EffortJointInterface</hardwareInterface>
            <mechanicalReduction>1</mechanicalReduction>
        </actuator>
    </transmission>
    <transmission name="trans_h0_F0_J1">
        <type>transmission_interface/SimpleTransmission</type>
        <joint name="h0_F0_J1">
            <hardwareInterface>hardware_interface/EffortJointInterface</hardwareInterface>
        </joint>
        <actuator name="h0_F0_J1_motor">
            <hardwareInterface>hardware_interface/EffortJointInterface</hardwareInterface>
            <mechanicalReduction>1</mechanicalReduction>
        </actuator>
    </transmission>
    <transmission name="trans_h0_F0_J2">
        <type>transmission_interface/SimpleTransmission</type>
        <joint name="h0_F0_J2">
            <hardwareInterface>hardware_interface/EffortJointInterface</hardwareInterface>
        </joint>
        <actuator name="h0_F0_J2_motor">
            <hardwareInterface>hardware_interface/EffortJointInterface</hardwareInterface>
            <mechanicalReduction>1</mechanicalReduction>
        </actuator>
    </transmission>
    <transmission name="trans_h0_F0_J3">
        <type>transmission_interface/SimpleTransmission</type>
        <joint name="h0_F0_J3">
            <hardwareInterface>hardware_interface/EffortJointInterface</hardwareInterface>
        </joint>
        <actuator name="h0_F0_J3_motor">
            <hardwareInterface>hardware_interface/EffortJointInterface</hardwareInterface>
            <mechanicalReduction>1</mechanicalReduction>
        </actuator>
    </transmission>
    <transmission name="trans_h0_F1_J0">
        <type>transmission_interface/SimpleTransmission</type>
        <joint name="h0_F1_J0">
            <hardwareInterface>hardware_interface/EffortJointInterface</hardwareInterface>
        </joint>
        <actuator name="h0_F1_J0_motor">
            <hardwareInterface>hardware_interface/EffortJointInterface</hardwareInterface>
            <mechanicalReduction>1</mechanicalReduction>
        </actuator>
    </transmission>
    <transmission name="trans_h0_F1_J1">
        <type>transmission_interface/SimpleTransmission</type>
        <joint name="h0_F1_J1">
            <hardwareInterface>hardware_interface/EffortJointInterface</hardwareInterface>
        </joint>
        <actuator name="h0_F1_J1_motor">
            <hardwareInterface>hardware_interface/EffortJointInterface</hardwareInterface>
            <mechanicalReduction>1</mechanicalReduction>
        </actuator>
    </transmission>
    <transmission name="trans_h0_F1_J2">
        <type>transmission_interface/SimpleTransmission</type>
        <joint name="h0_F1_J2">
            <hardwareInterface>hardware_interface/EffortJointInterface</hardwareInterface>
        </joint>
        <actuator name="h0_F1_J2_motor">
            <hardwareInterface>hardware_interface/EffortJointInterface</hardwareInterface>
            <mechanicalReduction>1</mechanicalReduction>
        </actuator>
    </transmission>
    <transmission name="trans_h0_F1_J3">
        <type>transmission_interface/SimpleTransmission</type>
        <joint name="h0_F1_J3">
            <hardwareInterface>hardware_interface/EffortJointInterface</hardwareInterface>
        </joint>
        <actuator name="h0_F1_J3_motor">
            <hardwareInterface>hardware_interface/EffortJointInterface</hardwareInterface>
            <mechanicalReduction>1</mechanicalReduction>
        </actuator>
    </transmission>
    <transmission name="trans_h0_F2_J0">
        <type>transmission_interface/SimpleTransmission</type>
        <joint name="h0_F2_J0">
            <hardwareInterface>hardware_interface/EffortJointInterface</hardwareInterface>
        </joint>
        <actuator name="h0_F2_J0_motor">
            <hardwareInterface>hardware_interface/EffortJointInterface</hardwareInterface>
            <mechanicalReduction>1</mechanicalReduction>
        </actuator>
    </transmission>
    <transmission name="trans_h0_F2_J1">
        <type>transmission_interface/SimpleTransmission</type>
        <joint name="h0_F2_J1">
            <hardwareInterface>hardware_interface/EffortJointInterface</hardwareInterface>
        </joint>
        <actuator name="h0_F2_J1_motor">
            <hardwareInterface>hardware_interface/EffortJointInterface</hardwareInterface>
            <mechanicalReduction>1</mechanicalReduction>
        </actuator>
    </transmission>
    <transmission name="trans_h0_F2_J2">
        <type>transmission_interface/SimpleTransmission</type>
        <joint name="h0_F2_J2">
            <hardwareInterface>hardware_interface/EffortJointInterface</hardwareInterface>
        </joint>
        <actuator name="h0_F2_J2_motor">
            <hardwareInterface>hardware_interface/EffortJointInterface</hardwareInterface>
            <mechanicalReduction>1</mechanicalReduction>
        </actuator>
    </transmission>
    <transmission name="trans_h0_F2_J3">
        <type>transmission_interface/SimpleTransmission</type>
        <joint name="h0_F2_J3">
            <hardwareInterface>hardware_interface/EffortJointInterface</hardwareInterface>
        </joint>
        <actuator name="h0_F2_J3_motor">
            <hardwareInterface>hardware_interface/EffortJointInterface</hardwareInterface>
            <mechanicalReduction>1</mechanicalReduction>
        </actuator>
    </transmission>
</robot>

